Workbook

Sheet Current prices, current borders
B2: Imports | L2: Exports
B3: Australia | C3: British settlement Oceania | D3: Dutch new Guinea | E3: French Polinesia | F3: German colonies Oceania | G3: Hawai | H3: New Zeland | I3: US settlement Oceania | L3: Australia | M3: British settlement Oceania | N3: Dutch new Guinea | O3: French Polinesia | P3: German colonies Oceania | Q3: Hawai | R3: New Zeland | S3: US settlement Oceania | V3: Australia | W3: British settlement Oceania | X3: Dutch new Guinea | Y3: French Polinesia | Z3: German colonies Oceania | AA3: Hawai | AB3: New Zeland | AC3: US settlement Oceania | AF3: Australia | AG3: British settlement Oceania | AH3: Dutch new Guinea | AI3: French Polinesia | AJ3: German colonies Oceania | AK3: Hawai | AL3: New Zeland | AM3: US settlement Oceania
B4: Millons $ | L4: Millons $ | V4: Australia | W4: French Polinesia | X4: Hawai | Y4: New Zeland | AA4: Australia | AB4: French Polinesia | AC4: Hawai | AD4: New Zeland | AF4: Australia | AG4: French Polinesia | AH4: Hawai | AI4: New Zeland
A7: 1800 | AA7: =+IF(B7>0,1," ")
A8: 1801 | AA8: =+IF(B8>0,1," ")
A9: 1802 | AA9: =+IF(B9>0,1," ")
A10: 1803 | AA10: =+IF(B10>0,1," ")
A11: 1804 | AA11: =+IF(B11>0,1," ")
A12: 1805 | AA12: =+IF(B12>0,1," ")
A13: 1806 | AA13: =+IF(B13>0,1," ")
A14: 1807 | AA14: =+IF(B14>0,1," ")
A15: 1808 | AA15: =+IF(B15>0,1," ")
A16: 1809 | AA16: =+IF(B16>0,1," ")
A17: 1810 | AA17: =+IF(B17>0,1," ")
A18: 1811 | AA18: =+IF(B18>0,1," ")
... A24: 1817 | AA24: =+IF(B24>0,1," ")
A25: 1818 | V25: =+IF(B25>0,1," ") | AA25: =+IF(B25>0,1," ")
A26: 1819 | V26: =+IF(B26>0,1," ") | AA26: =+IF(B26>0,1," ")
A27: 1820 | V27: =+IF(B27>0,1," ") | AA27: =+IF(B27>0,1," ")
A28: 1821 | V28: =+IF(B28>0,1," ") | AA28: =+IF(B28>0,1," ")
A29: 1822 | V29: =+IF(B29>0,1," ") | AA29: =+IF(B29>0,1," ")
A30: 1823 | V30: =+IF(B30>0,1," ") | AA30: =+IF(B30>0,1," ")
A31: 1824 | V31: =+IF(B31>0,1," ") | AA31: =+IF(B31>0,1," ")
A32: 1825 | V32: =+IF(B32>0,1," ") | AA32: =+IF(B32>0,1," ")
A33: 1826 | B33: 1.92864 | L33: 0.48216 | Q33: 0.037920667 | R33: 0.004587332 | V33: =+IF(B33>0,1," ") -> 1 | W33: =+IF(C33>0,1," ") | X33: =+IF(D33>0,1," ") | Y33: =+IF(E33>0,1," ") | Z33: =+IF(F33>0,1," ") | AA33: =+IF(G33>0,1," ") | AB33: =+IF(H33>0,1," ") | AC33: =+IF(I33>0,1," ") | AD33: =+IF(J33>0,1," ") | AF33: =+IF(L33>0,1," ") -> 1 | AG33: =+IF(M33>0,1," ") | AH33: =+IF(N33>0,1," ") | AI33: =+IF(O33>0,1," ") | AJ33: =+IF(P33>0,1," ") | AK33: =+IF(Q33>0,1," ") -> 1 | AL33: =+IF(R33>0,1," ") -> 1 | AM33: =+IF(S33>0,1," ") | AN33: =+IF(T33>0,1," ")
A34: 1827 | B34: 2.4004 | L34: 0.48008 | Q34: 0.039953853 | R34: 0.0048484175 | V34: =+IF(B34>0,1," ") -> 1 | W34: =+IF(C34>0,1," ") | X34: =+IF(D34>0,1," ") | Y34: =+IF(E34>0,1," ") | Z34: =+IF(F34>0,1," ") | AA34: =+IF(G34>0,1," ") | AB34: =+IF(H34>0,1," ") | AC34: =+IF(I34>0,1," ") | AD34: =+IF(J34>0,1," ") | AF34: =+IF(L34>0,1," ") -> 1 | AG34: =+IF(M34>0,1," ") | AH34: =+IF(N34>0,1," ") | AI34: =+IF(O34>0,1," ") | AJ34: =+IF(P34>0,1," ") | AK34: =+IF(Q34>0,1," ") -> 1 | AL34: =+IF(R34>0,1," ") -> 1 | AM34: =+IF(S34>0,1," ") | AN34: =+IF(T34>0,1," ")
A35: 1828 | B35: 3.45849 | L35: 0.49407 | Q35: 0.038177176 | R35: 0.0046258713 | V35: =+IF(B35>0,1," ") -> 1 | W35: =+IF(C35>0,1," ") | X35: =+IF(D35>0,1," ") | Y35: =+IF(E35>0,1," ") | Z35: =+IF(F35>0,1," ") | AA35: =+IF(G35>0,1," ") | AB35: =+IF(H35>0,1," ") | AC35: =+IF(I35>0,1," ") | AD35: =+IF(J35>0,1," ") | AF35: =+IF(L35>0,1," ") -> 1 | AG35: =+IF(M35>0,1," ") | AH35: =+IF(N35>0,1," ") | AI35: =+IF(O35>0,1," ") | AJ35: =+IF(P35>0,1," ") | AK35: =+IF(Q35>0,1," ") -> 1 | AL35: =+IF(R35>0,1," ") -> 1 | AM35: =+IF(S35>0,1," ") | AN35: =+IF(T35>0,1," ")
A36: 1829 | B36: 3.94864 | L36: 0.98716 | Q36: 0.076275326 | R36: 0.0091176479 | V36: =+IF(B36>0,1," ") -> 1 | W36: =+IF(C36>0,1," ") | X36: =+IF(D36>0,1," ") | Y36: =+IF(E36>0,1," ") | Z36: =+IF(F36>0,1," ") | AA36: =+IF(G36>0,1," ") | AB36: =+IF(H36>0,1," ") | AC36: =+IF(I36>0,1," ") | AD36: =+IF(J36>0,1," ") | AF36: =+IF(L36>0,1," ") -> 1 | AG36: =+IF(M36>0,1," ") | AH36: =+IF(N36>0,1," ") | AI36: =+IF(O36>0,1," ") | AJ36: =+IF(P36>0,1," ") | AK36: =+IF(Q36>0,1," ") -> 1 | AL36: =+IF(R36>0,1," ") -> 1 | AM36: =+IF(S36>0,1," ") | AN36: =+IF(T36>0,1," ")
A37: 1830 | B37: 3.36056 | L37: 0.96016 | Q37: 0.076230843 | R37: 0.0089241616 | V37: =+IF(B37>0,1," ") -> 1 | W37: =+IF(C37>0,1," ") | X37: =+IF(D37>0,1," ") | Y37: =+IF(E37>0,1," ") | Z37: =+IF(F37>0,1," ") | AA37: =+IF(G37>0,1," ") | AB37: =+IF(H37>0,1," ") | AC37: =+IF(I37>0,1," ") | AD37: =+IF(J37>0,1," ") | AF37: =+IF(L37>0,1," ") -> 1 | AG37: =+IF(M37>0,1," ") | AH37: =+IF(N37>0,1," ") | AI37: =+IF(O37>0,1," ") | AJ37: =+IF(P37>0,1," ") | AK37: =+IF(Q37>0,1," ") -> 1 | AL37: =+IF(R37>0,1," ") -> 1 | AM37: =+IF(S37>0,1," ") | AN37: =+IF(T37>0,1," ")
A38: 1831 | B38: 3.9604 | L38: 1.9802 | Q38: 0.15872831 | R38: 0.018966334 | V38: =+IF(B38>0,1," ") -> 1 | W38: =+IF(C38>0,1," ") | X38: =+IF(D38>0,1," ") | Y38: =+IF(E38>0,1," ") | Z38: =+IF(F38>0,1," ") | AA38: =+IF(G38>0,1," ") | AB38: =+IF(H38>0,1," ") | AC38: =+IF(I38>0,1," ") | AD38: =+IF(J38>0,1," ") | AF38: =+IF(L38>0,1," ") -> 1 | AG38: =+IF(M38>0,1," ") | AH38: =+IF(N38>0,1," ") | AI38: =+IF(O38>0,1," ") | AJ38: =+IF(P38>0,1," ") | AK38: =+IF(Q38>0,1," ") -> 1 | AL38: =+IF(R38>0,1," ") -> 1 | AM38: =+IF(S38>0,1," ") | AN38: =+IF(T38>0,1," ")
A39: 1832 | B39: 4.902 | L39: 2.451 | Q39: 0.23472163 | R39: 0.028032873 | V39: =+IF(B39>0,1," ") -> 1 | W39: =+IF(C39>0,1," ") | X39: =+IF(D39>0,1," ") | Y39: =+IF(E39>0,1," ") | Z39: =+IF(F39>0,1," ") | AA39: =+IF(G39>0,1," ") | AB39: =+IF(H39>0,1," ") | AC39: =+IF(I39>0,1," ") | AD39: =+IF(J39>0,1," ") | AF39: =+IF(L39>0,1," ") -> 1 | AG39: =+IF(M39>0,1," ") | AH39: =+IF(N39>0,1," ") | AI39: =+IF(O39>0,1," ") | AJ39: =+IF(P39>0,1," ") | AK39: =+IF(Q39>0,1," ") -> 1 | AL39: =+IF(R39>0,1," ") -> 1 | AM39: =+IF(S39>0,1," ") | AN39: =+IF(T39>0,1," ")
A40: 1833 | B40: 4.7506 | L40: 2.3753 | Q40: 0.23618057 | R40: 0.027797743 | V40: =+IF(B40>0,1," ") -> 1 | W40: =+IF(C40>0,1," ") | X40: =+IF(D40>0,1," ") | Y40: =+IF(E40>0,1," ") | Z40: =+IF(F40>0,1," ") | AA40: =+IF(G40>0,1," ") | AB40: =+IF(H40>0,1," ") | AC40: =+IF(I40>0,1," ") | AD40: =+IF(J40>0,1," ") | AF40: =+IF(L40>0,1," ") -> 1 | AG40: =+IF(M40>0,1," ") | AH40: =+IF(N40>0,1," ") | AI40: =+IF(O40>0,1," ") | AJ40: =+IF(P40>0,1," ") | AK40: =+IF(Q40>0,1," ") -> 1 | AL40: =+IF(R40>0,1," ") -> 1 | AM40: =+IF(S40>0,1," ") | AN40: =+IF(T40>0,1," ")
A41: 1834 | B41: 6.69858 | L41: 3.82776 | Q41: 0.344 | R41: 0.039227597 | V41: =+IF(B41>0,1," ") -> 1 | W41: =+IF(C41>0,1," ") | X41: =+IF(D41>0,1," ") | Y41: =+IF(E41>0,1," ") | Z41: =+IF(F41>0,1," ") | AA41: =+IF(G41>0,1," ") | AB41: =+IF(H41>0,1," ") | AC41: =+IF(I41>0,1," ") | AD41: =+IF(J41>0,1," ") | AF41: =+IF(L41>0,1," ") -> 1 | AG41: =+IF(M41>0,1," ") | AH41: =+IF(N41>0,1," ") | AI41: =+IF(O41>0,1," ") | AJ41: =+IF(P41>0,1," ") | AK41: =+IF(Q41>0,1," ") -> 1 | AL41: =+IF(R41>0,1," ") -> 1 | AM41: =+IF(S41>0,1," ") | AN41: =+IF(T41>0,1," ")
A42: 1835 | B42: 8.04432 | L42: 4.52493 | Q42: 0.344 | R42: 0.046782675 | V42: =+IF(B42>0,1," ") -> 1 | W42: =+IF(C42>0,1," ") | X42: =+IF(D42>0,1," ") | Y42: =+IF(E42>0,1," ") | Z42: =+IF(F42>0,1," ") | AA42: =+IF(G42>0,1," ") | AB42: =+IF(H42>0,1," ") | AC42: =+IF(I42>0,1," ") | AD42: =+IF(J42>0,1," ") | AF42: =+IF(L42>0,1," ") -> 1 | AG42: =+IF(M42>0,1," ") | AH42: =+IF(N42>0,1," ") | AI42: =+IF(O42>0,1," ") | AJ42: =+IF(P42>0,1," ") | AK42: =+IF(Q42>0,1," ") -> 1 | AL42: =+IF(R42>0,1," ") -> 1 | AM42: =+IF(S42>0,1," ") | AN42: =+IF(T42>0,1," ")
A43: 1836 | B43: 8.45767 | L43: 4.9751 | Q43: 0.31211941 | R43: 0.053268152 | V43: =+IF(B43>0,1," ") -> 1 | W43: =+IF(C43>0,1," ") | X43: =+IF(D43>0,1," ") | Y43: =+IF(E43>0,1," ") | Z43: =+IF(F43>0,1," ") | AA43: =+IF(G43>0,1," ") | AB43: =+IF(H43>0,1," ") | AC43: =+IF(I43>0,1," ") | AD43: =+IF(J43>0,1," ") | AF43: =+IF(L43>0,1," ") -> 1 | AG43: =+IF(M43>0,1," ") | AH43: =+IF(N43>0,1," ") | AI43: =+IF(O43>0,1," ") | AJ43: =+IF(P43>0,1," ") | AK43: =+IF(Q43>0,1," ") -> 1 | AL43: =+IF(R43>0,1," ") -> 1 | AM43: =+IF(S43>0,1," ") | AN43: =+IF(T43>0,1," ")
A44: 1837 | B44: 8.02995 | L44: 5.3533 | Q44: 0.28319338 | R44: 0.063911316 | V44: =+IF(B44>0,1," ") -> 1 | W44: =+IF(C44>0,1," ") | X44: =+IF(D44>0,1," ") | Y44: =+IF(E44>0,1," ") | Z44: =+IF(F44>0,1," ") | AA44: =+IF(G44>0,1," ") | AB44: =+IF(H44>0,1," ") | AC44: =+IF(I44>0,1," ") | AD44: =+IF(J44>0,1," ") | AF44: =+IF(L44>0,1," ") -> 1 | AG44: =+IF(M44>0,1," ") | AH44: =+IF(N44>0,1," ") | AI44: =+IF(O44>0,1," ") | AJ44: =+IF(P44>0,1," ") | AK44: =+IF(Q44>0,1," ") -> 1 | AL44: =+IF(R44>0,1," ") -> 1 | AM44: =+IF(S44>0,1," ") | AN44: =+IF(T44>0,1," ")
... A56: 1849 | B56: 11.704 | L56: 11.23584 | Q56: 0.161 | R56: 0.6306209 | V56: =+IF(B56>0,1," ") -> 1 | W56: =+IF(C56>0,1," ") | X56: =+IF(D56>0,1," ") | Y56: =+IF(E56>0,1," ") | Z56: =+IF(F56>0,1," ") | AA56: =+IF(G56>0,1," ") | AB56: =+IF(H56>0,1," ") | AC56: =+IF(I56>0,1," ") | AD56: =+IF(J56>0,1," ") | AF56: =+IF(L56>0,1," ") -> 1 | AG56: =+IF(M56>0,1," ") | AH56: =+IF(N56>0,1," ") | AI56: =+IF(O56>0,1," ") | AJ56: =+IF(P56>0,1," ") | AK56: =+IF(Q56>0,1," ") -> 1 | AL56: =+IF(R56>0,1," ") -> 1 | AM56: =+IF(S56>0,1," ") | AN56: =+IF(T56>0,1," ")
A57: 1850 | B57: 14.8809 | C57: 0.59460363 | E57: 0.56239105 | F57: 0.31575293 | G57: 1.035 | H57: 1.168848 | L57: 13.39281 | M57: 0.14197027 | O57: 0.088879408 | P57: 0.067285238 | Q57: 0.443 | R57: 0.560073 | V57: =+IF(B57>0,1," ") -> 1 | W57: =+IF(C57>0,1," ") -> 1 | X57: =+IF(D57>0,1," ") | Y57: =+IF(E57>0,1," ") -> 1 | Z57: =+IF(F57>0,1," ") -> 1 | AA57: =+IF(G57>0,1," ") -> 1 | AB57: =+IF(H57>0,1," ") -> 1 | AC57: =+IF(I57>0,1," ") | AD57: =+IF(J57>0,1," ") | AF57: =+IF(L57>0,1," ") -> 1 | AG57: =+IF(M57>0,1," ") -> 1 | AH57: =+IF(N57>0,1," ") | AI57: =+IF(O57>0,1," ") -> 1 | AJ57: =+IF(P57>0,1," ") -> 1 | AK57: =+IF(Q57>0,1," ") -> 1 | AL57: =+IF(R57>0,1," ") -> 1 | AM57: =+IF(S57>0,1," ") | AN57: =+IF(T57>0,1," ")
A58: 1851 | B58: 15.6576 | C58: 1.068297 | E58: 1.0104221 | F58: 2.4467074 | G58: 1.824 | H58: 1.719445 | L58: 14.09184 | M58: 0.18916998 | O58: 0.11842843 | P58: 0.13538843 | Q58: 0.579 | R58: 0.4126668 | V58: =+IF(B58>0,1," ") -> 1 | W58: =+IF(C58>0,1," ") -> 1 | X58: =+IF(D58>0,1," ") | Y58: =+IF(E58>0,1," ") -> 1 | Z58: =+IF(F58>0,1," ") -> 1 | AA58: =+IF(G58>0,1," ") -> 1 | AB58: =+IF(H58>0,1," ") -> 1 | AC58: =+IF(I58>0,1," ") | AD58: =+IF(J58>0,1," ") | AF58: =+IF(L58>0,1," ") -> 1 | AG58: =+IF(M58>0,1," ") -> 1 | AH58: =+IF(N58>0,1," ") | AI58: =+IF(O58>0,1," ") -> 1 | AJ58: =+IF(P58>0,1," ") -> 1 | AK58: =+IF(Q58>0,1," ") -> 1 | AL58: =+IF(R58>0,1," ") -> 1 | AM58: =+IF(S58>0,1," ") | AN58: =+IF(T58>0,1," ")
A59: 1852 | B59: 25.5864 | C59: 0.44019811 | E59: 0.41635043 | F59: 0.23795203 | G59: 0.76 | H59: 1.7597462 | L59: 58.10245 | M59: 0.16510566 | O59: 0.10336314 | P59: 0.1517605 | Q59: 0.511 | R59: 0.7156628 | V59: =+IF(B59>0,1," ") -> 1 | W59: =+IF(C59>0,1," ") -> 1 | X59: =+IF(D59>0,1," ") | Y59: =+IF(E59>0,1," ") -> 1 | Z59: =+IF(F59>0,1," ") -> 1 | AA59: =+IF(G59>0,1," ") -> 1 | AB59: =+IF(H59>0,1," ") -> 1 | AC59: =+IF(I59>0,1," ") | AD59: =+IF(J59>0,1," ") | AF59: =+IF(L59>0,1," ") -> 1 | AG59: =+IF(M59>0,1," ") -> 1 | AH59: =+IF(N59>0,1," ") | AI59: =+IF(O59>0,1," ") -> 1 | AJ59: =+IF(P59>0,1," ") -> 1 | AK59: =+IF(Q59>0,1," ") -> 1 | AL59: =+IF(R59>0,1," ") -> 1 | AM59: =+IF(S59>0,1," ") | AN59: =+IF(T59>0,1," ")
...

Sheet Current prices, 1913 borders
B2: Imports | L2: Exports
B3: Australia | C3: British settlement Oceania | D3: Dutch new Guinea | E3: French Polinesia | F3: German colonies Oceania | G3: Hawai | H3: New Zeland | I3: US settlement Oceania | L3: Australia | M3: British settlement Oceania | N3: Dutch new Guinea | O3: French Polinesia | P3: German colonies Oceania | Q3: Hawai | R3: New Zeland | S3: US settlement Oceania
B4: Millons $ | L4: Millons $
A7: 1800
A8: 1801
A9: 1802
A10: 1803
A11: 1804
A12: 1805
A13: 1806
A14: 1807
A15: 1808
A16: 1809
A17: 1810
A18: 1811
... A32: 1825
A33: 1826 | B33: 1.92864 | L33: 0.48216 | Q33: 0.00056866366 | R33: 0.004587332
A34: 1827 | B34: 2.4004 | L34: 0.48008 | Q34: 0.00059915359 | R34: 0.0048484175
A35: 1828 | B35: 3.45849 | L35: 0.49407 | Q35: 0.0005725103 | R35: 0.0046258713
A36: 1829 | B36: 3.94864 | L36: 0.98716 | Q36: 0.0011438355 | R36: 0.0091176479
A37: 1830 | B37: 3.36056 | L37: 0.96016 | Q37: 0.0011431685 | R37: 0.0089241616
A38: 1831 | B38: 3.9604 | L38: 1.9802 | Q38: 0.0023803121 | R38: 0.018966334
A39: 1832 | B39: 4.902 | L39: 2.451 | Q39: 0.0035199186 | R39: 0.028032873
A40: 1833 | B40: 4.7506 | L40: 2.3753 | Q40: 0.003541797 | R40: 0.027797743
A41: 1834 | B41: 6.69858 | L41: 3.82776 | Q41: 0.0051586724 | R41: 0.039227597
A42: 1835 | B42: 8.04432 | L42: 4.52493 | Q42: 0.0051586724 | R42: 0.046782675
A43: 1836 | B43: 8.45767 | L43: 4.9751 | Q43: 0.0046805865 | R43: 0.053268152
A44: 1837 | B44: 8.02995 | L44: 5.3533 | Q44: 0.0042468078 | R44: 0.063911316
... A56: 1849 | B56: 11.704 | L56: 11.23584 | Q56: 0.0024143787 | R56: 0.6306209
A57: 1850 | B57: 14.8809 | C57: 0.59460363 | E57: 0.56239105 | F57: 0.31575293 | G57: 0.446 | H57: 1.168848 | L57: 13.39281 | M57: 0.14197027 | O57: 0.088879408 | P57: 0.067285238 | Q57: 0.0066432903 | R57: 0.560073
A58: 1851 | B58: 15.6576 | C58: 1.068297 | E58: 1.0104221 | F58: 2.4467074 | G58: 0.905 | H58: 1.719445 | L58: 14.09184 | M58: 0.18916998 | O58: 0.11842843 | P58: 0.13538843 | Q58: 0.0086827655 | R58: 0.4126668
A59: 1852 | B59: 25.5864 | C59: 0.44019811 | E59: 0.41635043 | F59: 0.23795203 | G59: 0.296 | H59: 1.7597462 | L59: 58.10245 | M59: 0.16510566 | O59: 0.10336314 | P59: 0.1517605 | Q59: 0.0076630279 | R59: 0.7156628
A60: 1853 | B60: 72.0465 | C60: 0.76800975 | E60: 0.72640291 | F60: 0.60108615 | G60: 0.208 | H60: 2.9228446 | L60: 69.16464 | M60: 0.11212897 | O60: 0.070197491 | P60: 0.055990174 | Q60: 0.0051886647 | R60: 1.4809731
A61: 1854 | B61: 103.1175 | C61: 0.92715893 | E61: 0.8769302 | F61: 1.0162401 | G61: 0.461 | H61: 4.3503966 | L61: 63.7037 | M61: 0.14043464 | O61: 0.087918035 | P61: 0.09286409 | Q61: 0.0064783328 | R61: 1.5673146
A62: 1855 | B62: 68.02128 | C62: 0.80065049 | E62: 0.75727534 | F62: 0.9129136 | G62: 0.467 | H62: 3.9724806 | L62: 71.32787 | M62: 0.13305294 | O62: 0.083296783 | P62: 0.095725821 | Q62: 0.00617841 | R62: 1.7883492
A63: 1856 | B63: 80.03856 | C63: 0.66723691 | E63: 0.63108942 | F63: 0.64151974 | G63: 0.494 | H63: 3.4902279 | L63: 78.10992 | M63: 0.11631522 | O63: 0.07281826 | P63: 0.055614755 | Q63: 0.0053986107 | R63: 1.5610302
A64: 1857 | B64: 89.61624 | C64: 0.65367407 | E64: 0.61826135 | F64: 0.63828207 | G64: 0.383 | H64: 4.8543798 | L64: 76.33976 | M64: 0.15166562 | O64: 0.094949108 | P64: 0.078794925 | Q64: 0.0070481861 | R64: 1.8038934
A65: 1858 | B65: 85.7565 | C65: 0.62914248 | E65: 0.59505876 | F65: 0.4167973 | G65: 0.338 | H65: 5.5424075 | L65: 70.737 | M65: 0.18159676 | O65: 0.11368727 | P65: 0.086637788 | Q65: 0.0084578234 | R65: 2.224735
A66: 1859 | B66: 99.22152 | C66: 0.90408438 | E66: 0.85510571 | F66: 1.087652 | G66: 0.562 | H66: 7.5831492 | L66: 82.6846 | M66: 0.23984881 | O66: 0.15015552 | P66: 0.16422011 | Q66: 0.011097144 | R66: 2.7428412
A67: 1860 | B67: 93.73625 | C67: 0.70498529 | E67: 0.66679279 | F67: 1.0806692 | G67: 0.348 | H67: 7.5067164 | L67: 73.61725 | M67: 0.21751729 | O67: 0.13617504 | P67: 0.15825346 | Q67: 0.010152387 | R67: 2.8562377
...

Sheet Constant prices, current border
B2: Imports | L2: Exports | W2: Differenza current-1913 borders
B3: Australia | C3: British settlement Oceania | D3: Dutch new Guinea | E3: French Polinesia | F3: German colonies Oceania | G3: Hawai | H3: New Zeland | I3: US settlement Oceania | L3: Australia | M3: British settlement Oceania | N3: Dutch new Guinea | O3: French Polinesia | P3: German colonies Oceania | Q3: Hawai | R3: New Zeland | S3: US settlement Oceania
B4: Millons 1913$ | L4: Millons 1913$ | W4: Australia | X4: British settlement Oceania | Y4: Dutch new Guinea | Z4: French Polinesia | AA4: German colonies Oceania | AB4: Hawai | AC4: New Zeland | AD4: US settlement Oceania | AF4: Number
A7: 1800 | W7: =L7-'Constant prices, 1913 borders'!L7 -> 0 | X7: =M7-'Constant prices, 1913 borders'!M7 -> 0 | Y7: =N7-'Constant prices, 1913 borders'!N7 -> 0 | Z7: =O7-'Constant prices, 1913 borders'!O7 -> 0 | AA7: =P7-'Constant prices, 1913 borders'!P7 -> 0 | AB7: =Q7-'Constant prices, 1913 borders'!Q7 -> 0 | AC7: =R7-'Constant prices, 1913 borders'!R7 -> 0 | AD7: =S7-'Constant prices, 1913 borders'!S7 -> 0 | AF7: =+COUNTIF(W7:AD7,">0") -> 0
A8: 1801 | W8: =L8-'Constant prices, 1913 borders'!L8 -> 0 | X8: =M8-'Constant prices, 1913 borders'!M8 -> 0 | Y8: =N8-'Constant prices, 1913 borders'!N8 -> 0 | Z8: =O8-'Constant prices, 1913 borders'!O8 -> 0 | AA8: =P8-'Constant prices, 1913 borders'!P8 -> 0 | AB8: =Q8-'Constant prices, 1913 borders'!Q8 -> 0 | AC8: =R8-'Constant prices, 1913 borders'!R8 -> 0 | AD8: =S8-'Constant prices, 1913 borders'!S8 -> 0 | AF8: =+COUNTIF(W8:AD8,">0") -> 0
A9: 1802 | W9: =L9-'Constant prices, 1913 borders'!L9 -> 0 | X9: =M9-'Constant prices, 1913 borders'!M9 -> 0 | Y9: =N9-'Constant prices, 1913 borders'!N9 -> 0 | Z9: =O9-'Constant prices, 1913 borders'!O9 -> 0 | AA9: =P9-'Constant prices, 1913 borders'!P9 -> 0 | AB9: =Q9-'Constant prices, 1913 borders'!Q9 -> 0 | AC9: =R9-'Constant prices, 1913 borders'!R9 -> 0 | AD9: =S9-'Constant prices, 1913 borders'!S9 -> 0 | AF9: =+COUNTIF(W9:AD9,">0") -> 0
A10: 1803 | W10: =L10-'Constant prices, 1913 borders'!L10 -> 0 | X10: =M10-'Constant prices, 1913 borders'!M10 -> 0 | Y10: =N10-'Constant prices, 1913 borders'!N10 -> 0 | Z10: =O10-'Constant prices, 1913 borders'!O10 -> 0 | AA10: =P10-'Constant prices, 1913 borders'!P10 -> 0 | AB10: =Q10-'Constant prices, 1913 borders'!Q10 -> 0 | AC10: =R10-'Constant prices, 1913 borders'!R10 -> 0 | AD10: =S10-'Constant prices, 1913 borders'!S10 -> 0 | AF10: =+COUNTIF(W10:AD10,">0") -> 0
A11: 1804 | W11: =L11-'Constant prices, 1913 borders'!L11 -> 0 | X11: =M11-'Constant prices, 1913 borders'!M11 -> 0 | Y11: =N11-'Constant prices, 1913 borders'!N11 -> 0 | Z11: =O11-'Constant prices, 1913 borders'!O11 -> 0 | AA11: =P11-'Constant prices, 1913 borders'!P11 -> 0 | AB11: =Q11-'Constant prices, 1913 borders'!Q11 -> 0 | AC11: =R11-'Constant prices, 1913 borders'!R11 -> 0 | AD11: =S11-'Constant prices, 1913 borders'!S11 -> 0 | AF11: =+COUNTIF(W11:AD11,">0") -> 0
A12: 1805 | W12: =L12-'Constant prices, 1913 borders'!L12 -> 0 | X12: =M12-'Constant prices, 1913 borders'!M12 -> 0 | Y12: =N12-'Constant prices, 1913 borders'!N12 -> 0 | Z12: =O12-'Constant prices, 1913 borders'!O12 -> 0 | AA12: =P12-'Constant prices, 1913 borders'!P12 -> 0 | AB12: =Q12-'Constant prices, 1913 borders'!Q12 -> 0 | AC12: =R12-'Constant prices, 1913 borders'!R12 -> 0 | AD12: =S12-'Constant prices, 1913 borders'!S12 -> 0 | AF12: =+COUNTIF(W12:AD12,">0") -> 0
A13: 1806 | W13: =L13-'Constant prices, 1913 borders'!L13 -> 0 | X13: =M13-'Constant prices, 1913 borders'!M13 -> 0 | Y13: =N13-'Constant prices, 1913 borders'!N13 -> 0 | Z13: =O13-'Constant prices, 1913 borders'!O13 -> 0 | AA13: =P13-'Constant prices, 1913 borders'!P13 -> 0 | AB13: =Q13-'Constant prices, 1913 borders'!Q13 -> 0 | AC13: =R13-'Constant prices, 1913 borders'!R13 -> 0 | AD13: =S13-'Constant prices, 1913 borders'!S13 -> 0 | AF13: =+COUNTIF(W13:AD13,">0") -> 0
A14: 1807 | W14: =L14-'Constant prices, 1913 borders'!L14 -> 0 | X14: =M14-'Constant prices, 1913 borders'!M14 -> 0 | Y14: =N14-'Constant prices, 1913 borders'!N14 -> 0 | Z14: =O14-'Constant prices, 1913 borders'!O14 -> 0 | AA14: =P14-'Constant prices, 1913 borders'!P14 -> 0 | AB14: =Q14-'Constant prices, 1913 borders'!Q14 -> 0 | AC14: =R14-'Constant prices, 1913 borders'!R14 -> 0 | AD14: =S14-'Constant prices, 1913 borders'!S14 -> 0 | AF14: =+COUNTIF(W14:AD14,">0") -> 0
A15: 1808 | W15: =L15-'Constant prices, 1913 borders'!L15 -> 0 | X15: =M15-'Constant prices, 1913 borders'!M15 -> 0 | Y15: =N15-'Constant prices, 1913 borders'!N15 -> 0 | Z15: =O15-'Constant prices, 1913 borders'!O15 -> 0 | AA15: =P15-'Constant prices, 1913 borders'!P15 -> 0 | AB15: =Q15-'Constant prices, 1913 borders'!Q15 -> 0 | AC15: =R15-'Constant prices, 1913 borders'!R15 -> 0 | AD15: =S15-'Constant prices, 1913 borders'!S15 -> 0 | AF15: =+COUNTIF(W15:AD15,">0") -> 0
A16: 1809 | W16: =L16-'Constant prices, 1913 borders'!L16 -> 0 | X16: =M16-'Constant prices, 1913 borders'!M16 -> 0 | Y16: =N16-'Constant prices, 1913 borders'!N16 -> 0 | Z16: =O16-'Constant prices, 1913 borders'!O16 -> 0 | AA16: =P16-'Constant prices, 1913 borders'!P16 -> 0 | AB16: =Q16-'Constant prices, 1913 borders'!Q16 -> 0 | AC16: =R16-'Constant prices, 1913 borders'!R16 -> 0 | AD16: =S16-'Constant prices, 1913 borders'!S16 -> 0 | AF16: =+COUNTIF(W16:AD16,">0") -> 0
A17: 1810 | W17: =L17-'Constant prices, 1913 borders'!L17 -> 0 | X17: =M17-'Constant prices, 1913 borders'!M17 -> 0 | Y17: =N17-'Constant prices, 1913 borders'!N17 -> 0 | Z17: =O17-'Constant prices, 1913 borders'!O17 -> 0 | AA17: =P17-'Constant prices, 1913 borders'!P17 -> 0 | AB17: =Q17-'Constant prices, 1913 borders'!Q17 -> 0 | AC17: =R17-'Constant prices, 1913 borders'!R17 -> 0 | AD17: =S17-'Constant prices, 1913 borders'!S17 -> 0 | AF17: =+COUNTIF(W17:AD17,">0") -> 0
A18: 1811 | W18: =L18-'Constant prices, 1913 borders'!L18 -> 0 | X18: =M18-'Constant prices, 1913 borders'!M18 -> 0 | Y18: =N18-'Constant prices, 1913 borders'!N18 -> 0 | Z18: =O18-'Constant prices, 1913 borders'!O18 -> 0 | AA18: =P18-'Constant prices, 1913 borders'!P18 -> 0 | AB18: =Q18-'Constant prices, 1913 borders'!Q18 -> 0 | AC18: =R18-'Constant prices, 1913 borders'!R18 -> 0 | AD18: =S18-'Constant prices, 1913 borders'!S18 -> 0 | AF18: =+COUNTIF(W18:AD18,">0") -> 0
... A32: 1825 | W32: =L32-'Constant prices, 1913 borders'!L32 -> 0 | X32: =M32-'Constant prices, 1913 borders'!M32 -> 0 | Y32: =N32-'Constant prices, 1913 borders'!N32 -> 0 | Z32: =O32-'Constant prices, 1913 borders'!O32 -> 0 | AA32: =P32-'Constant prices, 1913 borders'!P32 -> 0 | AB32: =Q32-'Constant prices, 1913 borders'!Q32 -> 0 | AC32: =R32-'Constant prices, 1913 borders'!R32 -> 0 | AD32: =S32-'Constant prices, 1913 borders'!S32 -> 0 | AF32: =+COUNTIF(W32:AD32,">0") -> 0
A33: 1826 | B33: 1.6915229 | L33: 0.9909005 | Q33: 0.017998432 | R33: 0.0084533593 | W33: =L33-'Constant prices, 1913 borders'!L33 -> 0 | X33: =M33-'Constant prices, 1913 borders'!M33 -> 0 | Y33: =N33-'Constant prices, 1913 borders'!N33 -> 0 | Z33: =O33-'Constant prices, 1913 borders'!O33 -> 0 | AA33: =P33-'Constant prices, 1913 borders'!P33 -> 0 | AB33: =Q33-'Constant prices, 1913 borders'!Q33 -> 0.017728525 | AC33: =R33-'Constant prices, 1913 borders'!R33 -> 0 | AD33: =S33-'Constant prices, 1913 borders'!S33 -> 0 | AF33: =+COUNTIF(W33:AD33,">0") -> 1
A34: 1827 | B34: 2.1315113 | L34: 0.93997221 | Q34: 0.017136987 | R34: 0.007639876 | W34: =L34-'Constant prices, 1913 borders'!L34 -> 0 | X34: =M34-'Constant prices, 1913 borders'!M34 -> 0 | Y34: =N34-'Constant prices, 1913 borders'!N34 -> 0 | Z34: =O34-'Constant prices, 1913 borders'!O34 -> 0 | AA34: =P34-'Constant prices, 1913 borders'!P34 -> 0 | AB34: =Q34-'Constant prices, 1913 borders'!Q34 -> 0.016879998 | AC34: =R34-'Constant prices, 1913 borders'!R34 -> 0 | AD34: =S34-'Constant prices, 1913 borders'!S34 -> 0 | AF34: =+COUNTIF(W34:AD34,">0") -> 1
A35: 1828 | B35: 2.9617842 | L35: 0.9850369 | Q35: 0.016926266 | R35: 0.0080009409 | W35: =L35-'Constant prices, 1913 borders'!L35 -> 0 | X35: =M35-'Constant prices, 1913 borders'!M35 -> 0 | Y35: =N35-'Constant prices, 1913 borders'!N35 -> 0 | Z35: =O35-'Constant prices, 1913 borders'!O35 -> 0 | AA35: =P35-'Constant prices, 1913 borders'!P35 -> 0 | AB35: =Q35-'Constant prices, 1913 borders'!Q35 -> 0.016672437 | AC35: =R35-'Constant prices, 1913 borders'!R35 -> 0 | AD35: =S35-'Constant prices, 1913 borders'!S35 -> 0 | AF35: =+COUNTIF(W35:AD35,">0") -> 1
A36: 1829 | B36: 3.0247262 | L36: 1.9769637 | Q36: 0.037188312 | R36: 0.016094167 | W36: =L36-'Constant prices, 1913 borders'!L36 -> 0 | X36: =M36-'Constant prices, 1913 borders'!M36 -> 0 | Y36: =N36-'Constant prices, 1913 borders'!N36 -> 0 | Z36: =O36-'Constant prices, 1913 borders'!O36 -> 0 | AA36: =P36-'Constant prices, 1913 borders'!P36 -> 0 | AB36: =Q36-'Constant prices, 1913 borders'!Q36 -> 0.036630631 | AC36: =R36-'Constant prices, 1913 borders'!R36 -> 0 | AD36: =S36-'Constant prices, 1913 borders'!S36 -> 0 | AF36: =+COUNTIF(W36:AD36,">0") -> 1
A37: 1830 | B37: 2.7482812 | L37: 1.9773451 | Q37: 0.039250692 | R37: 0.017148027 | W37: =L37-'Constant prices, 1913 borders'!L37 -> 0 | X37: =M37-'Constant prices, 1913 borders'!M37 -> 0 | Y37: =N37-'Constant prices, 1913 borders'!N37 -> 0 | Z37: =O37-'Constant prices, 1913 borders'!O37 -> 0 | AA37: =P37-'Constant prices, 1913 borders'!P37 -> 0 | AB37: =Q37-'Constant prices, 1913 borders'!Q37 -> 0.038662083 | AC37: =R37-'Constant prices, 1913 borders'!R37 -> 0 | AD37: =S37-'Constant prices, 1913 borders'!S37 -> 0 | AF37: =+COUNTIF(W37:AD37,">0") -> 1
A38: 1831 | B38: 2.8904512 | L38: 3.7961076 | Q38: 0.091171772 | R38: 0.035562909 | W38: =L38-'Constant prices, 1913 borders'!L38 -> 0 | X38: =M38-'Constant prices, 1913 borders'!M38 -> 0 | Y38: =N38-'Constant prices, 1913 borders'!N38 -> 0 | Z38: =O38-'Constant prices, 1913 borders'!O38 -> 0 | AA38: =P38-'Constant prices, 1913 borders'!P38 -> 0 | AB38: =Q38-'Constant prices, 1913 borders'!Q38 -> 0.089804548 | AC38: =R38-'Constant prices, 1913 borders'!R38 -> 0 | AD38: =S38-'Constant prices, 1913 borders'!S38 -> 0 | AF38: =+COUNTIF(W38:AD38,">0") -> 1
A39: 1832 | B39: 3.8946074 | L39: 4.0098996 | Q39: 0.1293262 | R39: 0.047092356 | W39: =L39-'Constant prices, 1913 borders'!L39 -> 0 | X39: =M39-'Constant prices, 1913 borders'!M39 -> 0 | Y39: =N39-'Constant prices, 1913 borders'!N39 -> 0 | Z39: =O39-'Constant prices, 1913 borders'!O39 -> 0 | AA39: =P39-'Constant prices, 1913 borders'!P39 -> 0 | AB39: =Q39-'Constant prices, 1913 borders'!Q39 -> 0.12738681 | AC39: =R39-'Constant prices, 1913 borders'!R39 -> 0 | AD39: =S39-'Constant prices, 1913 borders'!S39 -> 0 | AF39: =+COUNTIF(W39:AD39,">0") -> 1
A40: 1833 | B40: 4.4800994 | L40: 3.9785796 | Q40: 0.12598839 | R40: 0.045855034 | W40: =L40-'Constant prices, 1913 borders'!L40 -> 0 | X40: =M40-'Constant prices, 1913 borders'!M40 -> 0 | Y40: =N40-'Constant prices, 1913 borders'!N40 -> 0 | Z40: =O40-'Constant prices, 1913 borders'!O40 -> 0 | AA40: =P40-'Constant prices, 1913 borders'!P40 -> 0 | AB40: =Q40-'Constant prices, 1913 borders'!Q40 -> 0.12409905 | AC40: =R40-'Constant prices, 1913 borders'!R40 -> 0 | AD40: =S40-'Constant prices, 1913 borders'!S40 -> 0 | AF40: =+COUNTIF(W40:AD40,">0") -> 1
A41: 1834 | B41: 6.8694425 | L41: 6.9801895 | Q41: 0.18915673 | R41: 0.069455049 | W41: =L41-'Constant prices, 1913 borders'!L41 -> 0 | X41: =M41-'Constant prices, 1913 borders'!M41 -> 0 | Y41: =N41-'Constant prices, 1913 borders'!N41 -> 0 | Z41: =O41-'Constant prices, 1913 borders'!O41 -> 0 | AA41: =P41-'Constant prices, 1913 borders'!P41 -> 0 | AB41: =Q41-'Constant prices, 1913 borders'!Q41 -> 0.1863201 | AC41: =R41-'Constant prices, 1913 borders'!R41 -> 0 | AD41: =S41-'Constant prices, 1913 borders'!S41 -> 0 | AF41: =+COUNTIF(W41:AD41,">0") -> 1
A42: 1835 | B42: 7.7501446 | L42: 7.7490331 | Q42: 0.17271529 | R42: 0.084788459 | W42: =L42-'Constant prices, 1913 borders'!L42 -> 0 | X42: =M42-'Constant prices, 1913 borders'!M42 -> 0 | Y42: =N42-'Constant prices, 1913 borders'!N42 -> 0 | Z42: =O42-'Constant prices, 1913 borders'!O42 -> 0 | AA42: =P42-'Constant prices, 1913 borders'!P42 -> 0 | AB42: =Q42-'Constant prices, 1913 borders'!Q42 -> 0.17012523 | AC42: =R42-'Constant prices, 1913 borders'!R42 -> 0 | AD42: =S42-'Constant prices, 1913 borders'!S42 -> 0 | AF42: =+COUNTIF(W42:AD42,">0") -> 1
A43: 1836 | B43: 7.6308145 | L43: 8.3558834 | Q43: 0.1451676 | R43: 0.10494628 | W43: =L43-'Constant prices, 1913 borders'!L43 -> 0 | X43: =M43-'Constant prices, 1913 borders'!M43 -> 0 | Y43: =N43-'Constant prices, 1913 borders'!N43 -> 0 | Z43: =O43-'Constant prices, 1913 borders'!O43 -> 0 | AA43: =P43-'Constant prices, 1913 borders'!P43 -> 0 | AB43: =Q43-'Constant prices, 1913 borders'!Q43 -> 0.14299065 | AC43: =R43-'Constant prices, 1913 borders'!R43 -> 0 | AD43: =S43-'Constant prices, 1913 borders'!S43 -> 0 | AF43: =+COUNTIF(W43:AD43,">0") -> 1
A44: 1837 | B44: 6.2073302 | L44: 7.3796585 | Q44: 0.14116957 | R44: 0.11412528 | W44: =L44-'Constant prices, 1913 borders'!L44 -> 0 | X44: =M44-'Constant prices, 1913 borders'!M44 -> 0 | Y44: =N44-'Constant prices, 1913 borders'!N44 -> 0 | Z44: =O44-'Constant prices, 1913 borders'!O44 -> 0 | AA44: =P44-'Constant prices, 1913 borders'!P44 -> 0 | AB44: =Q44-'Constant prices, 1913 borders'!Q44 -> 0.13905257 | AC44: =R44-'Constant prices, 1913 borders'!R44 -> 0 | AD44: =S44-'Constant prices, 1913 borders'!S44 -> 0 | AF44: =+COUNTIF(W44:AD44,">0") -> 1
... A56: 1849 | B56: 11.531338 | L56: 12.776862 | Q56: 0.10327714 | R56: 0.92974819 | W56: =L56-'Constant prices, 1913 borders'!L56 -> 0 | X56: =M56-'Constant prices, 1913 borders'!M56 -> 0 | Y56: =N56-'Constant prices, 1913 borders'!N56 -> 0 | Z56: =O56-'Constant prices, 1913 borders'!O56 -> 0 | AA56: =P56-'Constant prices, 1913 borders'!P56 -> 0 | AB56: =Q56-'Constant prices, 1913 borders'!Q56 -> 0.10172838 | AC56: =R56-'Constant prices, 1913 borders'!R56 -> 0 | AD56: =S56-'Constant prices, 1913 borders'!S56 -> 0 | AF56: =+COUNTIF(W56:AD56,">0") -> 1
A57: 1850 | B57: 14.905336 | C57: 0.52575018 | E57: 0.50436047 | F57: 0.28564234 | G57: 0.76586225 | H57: 1.4436335 | L57: 17.983106 | M57: 0.31561833 | O57: 0.10314682 | P57: 0.20355474 | Q57: 0.27316016 | R57: 0.85879724 | W57: =L57-'Constant prices, 1913 borders'!L57 -> 0 | X57: =M57-'Constant prices, 1913 borders'!M57 -> 0 | Y57: =N57-'Constant prices, 1913 borders'!N57 -> 0 | Z57: =O57-'Constant prices, 1913 borders'!O57 -> 0 | AA57: =P57-'Constant prices, 1913 borders'!P57 -> 0 | AB57: =Q57-'Constant prices, 1913 borders'!Q57 -> 0.26906381 | AC57: =R57-'Constant prices, 1913 borders'!R57 -> 0 | AD57: =S57-'Constant prices, 1913 borders'!S57 -> 0 | AF57: =+COUNTIF(W57:AD57,">0") -> 1
A58: 1851 | B58: 15.073724 | C58: 0.92203869 | E58: 0.89309916 | F58: 2.1712886 | G58: 1.3123981 | H58: 2.1236312 | L58: 16.587491 | M58: 0.38383373 | O58: 0.16932924 | P58: 0.36153354 | Q58: 0.33701598 | R58: 0.57490858 | W58: =L58-'Constant prices, 1913 borders'!L58 -> 0 | X58: =M58-'Constant prices, 1913 borders'!M58 -> 0 | Y58: =N58-'Constant prices, 1913 borders'!N58 -> 0 | Z58: =O58-'Constant prices, 1913 borders'!O58 -> 0 | AA58: =P58-'Constant prices, 1913 borders'!P58 -> 0 | AB58: =Q58-'Constant prices, 1913 borders'!Q58 -> 0.33196204 | AC58: =R58-'Constant prices, 1913 borders'!R58 -> 0 | AD58: =S58-'Constant prices, 1913 borders'!S58 -> 0 | AF58: =+COUNTIF(W58:AD58,">0") -> 1
A59: 1852 | B59: 21.96152 | C59: 0.34426856 | E59: 0.32854509 | F59: 0.20231034 | G59: 0.49776007 | H59: 1.9708384 | L59: 62.451171 | M59: 0.36139584 | O59: 0.13721212 | P59: 0.43176816 | Q59: 0.3331724 | R59: 0.93841573 | W59: =L59-'Constant prices, 1913 borders'!L59 -> 0 | X59: =M59-'Constant prices, 1913 borders'!M59 -> 0 | Y59: =N59-'Constant prices, 1913 borders'!N59 -> 0 | Z59: =O59-'Constant prices, 1913 borders'!O59 -> 0 | AA59: =P59-'Constant prices, 1913 borders'!P59 -> 0 | AB59: =Q59-'Constant prices, 1913 borders'!Q59 -> 0.3281761 | AC59: =R59-'Constant prices, 1913 borders'!R59 -> 0 | AD59: =S59-'Constant prices, 1913 borders'!S59 -> 0 | AF59: =+COUNTIF(W59:AD59,">0") -> 1
A60: 1853 | B60: 50.735141 | C60: 0.4800285 | E60: 0.43789592 | F60: 0.4453329 | G60: 0.7104732 | H60: 2.4626268 | L60: 67.394578 | M60: 0.23090032 | O60: 0.084964833 | P60: 0.15384027 | Q60: 0.21417206 | R60: 1.5874368 | W60: =L60-'Constant prices, 1913 borders'!L60 -> 0 | X60: =M60-'Constant prices, 1913 borders'!M60 -> 0 | Y60: =N60-'Constant prices, 1913 borders'!N60 -> 0 | Z60: =O60-'Constant prices, 1913 borders'!O60 -> 0 | AA60: =P60-'Constant prices, 1913 borders'!P60 -> 0 | AB60: =Q60-'Constant prices, 1913 borders'!Q60 -> 0.2109603 | AC60: =R60-'Constant prices, 1913 borders'!R60 -> 0 | AD60: =S60-'Constant prices, 1913 borders'!S60 -> 0 | AF60: =+COUNTIF(W60:AD60,">0") -> 1
A61: 1854 | B61: 70.210718 | C61: 0.57233728 | E61: 0.46107064 | F61: 0.76257066 | G61: 0.7826545 | H61: 3.3380093 | L61: 60.757568 | M61: 0.25682923 | O61: 0.099523246 | P61: 0.20933075 | Q61: 0.30690136 | R61: 2.5214291 | W61: =L61-'Constant prices, 1913 borders'!L61 -> 0 | X61: =M61-'Constant prices, 1913 borders'!M61 -> 0 | Y61: =N61-'Constant prices, 1913 borders'!N61 -> 0 | Z61: =O61-'Constant prices, 1913 borders'!O61 -> 0 | AA61: =P61-'Constant prices, 1913 borders'!P61 -> 0 | AB61: =Q61-'Constant prices, 1913 borders'!Q61 -> 0.30229903 | AC61: =R61-'Constant prices, 1913 borders'!R61 -> 0 | AD61: =S61-'Constant prices, 1913 borders'!S61 -> 0 | AF61: =+COUNTIF(W61:AD61,">0") -> 1
A62: 1855 | B62: 49.205167 | C62: 0.55669654 | E62: 0.40536103 | F62: 0.7500432 | G62: 0.70672599 | H62: 3.2845329 | L62: 71.654666 | M62: 0.18595031 | O62: 0.10679701 | P62: 0.16129824 | Q62: 0.21724448 | R62: 2.149576 | W62: =L62-'Constant prices, 1913 borders'!L62 -> 0 | X62: =M62-'Constant prices, 1913 borders'!M62 -> 0 | Y62: =N62-'Constant prices, 1913 borders'!N62 -> 0 | Z62: =O62-'Constant prices, 1913 borders'!O62 -> 0 | AA62: =P62-'Constant prices, 1913 borders'!P62 -> 0 | AB62: =Q62-'Constant prices, 1913 borders'!Q62 -> 0.21398665 | AC62: =R62-'Constant prices, 1913 borders'!R62 -> 0 | AD62: =S62-'Constant prices, 1913 borders'!S62 -> 0 | AF62: =+COUNTIF(W62:AD62,">0") -> 1
A63: 1856 | B63: 59.29479 | C63: 0.49149883 | E63: 0.35811743 | F63: 0.55798657 | G63: 0.62529653 | H63: 3.0301442 | L63: 70.313954 | M63: 0.17723022 | O63: 0.088891331 | P63: 0.1084597 | Q63: 0.16497301 | R63: 1.5251332 | W63: =L63-'Constant prices, 1913 borders'!L63 -> 0 | X63: =M63-'Constant prices, 1913 borders'!M63 -> 0 | Y63: =N63-'Constant prices, 1913 borders'!N63 -> 0 | Z63: =O63-'Constant prices, 1913 borders'!O63 -> 0 | AA63: =P63-'Constant prices, 1913 borders'!P63 -> 0 | AB63: =Q63-'Constant prices, 1913 borders'!Q63 -> 0.16249905 | AC63: =R63-'Constant prices, 1913 borders'!R63 -> 0 | AD63: =S63-'Constant prices, 1913 borders'!S63 -> 0 | AF63: =+COUNTIF(W63:AD63,">0") -> 1
A64: 1857 | B64: 70.899808 | C64: 0.49042895 | E64: 0.39900989 | F64: 0.54548866 | G64: 0.67957729 | H64: 4.1104143 | L64: 62.624413 | M64: 0.19798675 | O64: 0.10261782 | P64: 0.13248363 | Q64: 0.16883272 | R64: 2.4626697 | W64: =L64-'Constant prices, 1913 borders'!L64 -> 0 | X64: =M64-'Constant prices, 1913 borders'!M64 -> 0 | Y64: =N64-'Constant prices, 1913 borders'!N64 -> 0 | Z64: =O64-'Constant prices, 1913 borders'!O64 -> 0 | AA64: =P64-'Constant prices, 1913 borders'!P64 -> 0 | AB64: =Q64-'Constant prices, 1913 borders'!Q64 -> 0.16630088 | AC64: =R64-'Constant prices, 1913 borders'!R64 -> 0 | AD64: =S64-'Constant prices, 1913 borders'!S64 -> 0 | AF64: =+COUNTIF(W64:AD64,">0") -> 1
A65: 1858 | B65: 76.337736 | C65: 0.51541768 | E65: 0.44488857 | F65: 0.37526679 | G65: 0.72690954 | H65: 4.9025439 | L65: 70.744439 | M65: 0.28460321 | O65: 0.14545297 | P65: 0.17102085 | Q65: 0.25807515 | R65: 3.1008477 | W65: =L65-'Constant prices, 1913 borders'!L65 -> 0 | X65: =M65-'Constant prices, 1913 borders'!M65 -> 0 | Y65: =N65-'Constant prices, 1913 borders'!N65 -> 0 | Z65: =O65-'Constant prices, 1913 borders'!O65 -> 0 | AA65: =P65-'Constant prices, 1913 borders'!P65 -> 0 | AB65: =Q65-'Constant prices, 1913 borders'!Q65 -> 0.25420502 | AC65: =R65-'Constant prices, 1913 borders'!R65 -> 0 | AD65: =S65-'Constant prices, 1913 borders'!S65 -> 0 | AF65: =+COUNTIF(W65:AD65,">0") -> 1
A66: 1859 | B66: 78.446551 | C66: 0.64366415 | E66: 0.59278204 | F66: 0.90143921 | G66: 0.97562946 | H66: 6.383238 | L66: 73.821357 | M66: 0.38166578 | O66: 0.15334184 | P66: 0.32737271 | Q66: 0.34002243 | R66: 3.6513646 | W66: =L66-'Constant prices, 1913 borders'!L66 -> 0 | X66: =M66-'Constant prices, 1913 borders'!M66 -> 0 | Y66: =N66-'Constant prices, 1913 borders'!N66 -> 0 | Z66: =O66-'Constant prices, 1913 borders'!O66 -> 0 | AA66: =P66-'Constant prices, 1913 borders'!P66 -> 0 | AB66: =Q66-'Constant prices, 1913 borders'!Q66 -> 0.33492341 | AC66: =R66-'Constant prices, 1913 borders'!R66 -> 0 | AD66: =S66-'Constant prices, 1913 borders'!S66 -> 0 | AF66: =+COUNTIF(W66:AD66,">0") -> 1
A67: 1860 | B67: 72.900026 | C67: 0.48609998 | E67: 0.43499258 | F67: 0.8891814 | G67: 0.74192843 | H67: 6.3360342 | L67: 65.317096 | M67: 0.27293281 | O67: 0.12170759 | P67: 0.23146667 | Q67: 0.30831598 | R67: 1.5391522 | W67: =L67-'Constant prices, 1913 borders'!L67 -> 0 | X67: =M67-'Constant prices, 1913 borders'!M67 -> 0 | Y67: =N67-'Constant prices, 1913 borders'!N67 -> 0 | Z67: =O67-'Constant prices, 1913 borders'!O67 -> 0 | AA67: =P67-'Constant prices, 1913 borders'!P67 -> 0 | AB67: =Q67-'Constant prices, 1913 borders'!Q67 -> 0.30369243 | AC67: =R67-'Constant prices, 1913 borders'!R67 -> 0 | AD67: =S67-'Constant prices, 1913 borders'!S67 -> 0 | AF67: =+COUNTIF(W67:AD67,">0") -> 1
...

Sheet Constant prices, 1913 borders
B2: Imports | L2: Exports
B3: Australia | C3: British settlement Oceania | D3: Dutch new Guinea | E3: French Polinesia | F3: German colonies Oceania | G3: Hawai | H3: New Zeland | I3: US settlement Oceania | L3: Australia | M3: British settlement Oceania | N3: Dutch new Guinea | O3: French Polinesia | P3: German colonies Oceania | Q3: Hawai | R3: New Zeland | S3: US settlement Oceania
B4: Millons 1913$ | L4: Millons 1913$
A7: 1800
A8: 1801
A9: 1802
A10: 1803
A11: 1804
A12: 1805
A13: 1806
A14: 1807
A15: 1808
A16: 1809
A17: 1810
A18: 1811
... A32: 1825
A33: 1826 | B33: 1.6915229 | L33: 0.9909005 | Q33: 0.00026990702 | R33: 0.0084533593
A34: 1827 | B34: 2.1315113 | L34: 0.93997221 | Q34: 0.00025698866 | R34: 0.007639876
A35: 1828 | B35: 2.9617842 | L35: 0.9850369 | Q35: 0.00025382867 | R35: 0.0080009409
A36: 1829 | B36: 3.0247262 | L36: 1.9769637 | Q36: 0.00055768116 | R36: 0.016094167
A37: 1830 | B37: 2.7482812 | L37: 1.9773451 | Q37: 0.0005886089 | R37: 0.017148027
A38: 1831 | B38: 2.8904512 | L38: 3.7961076 | Q38: 0.0013672247 | R38: 0.035562909
A39: 1832 | B39: 3.8946074 | L39: 4.0098996 | Q39: 0.0019393939 | R39: 0.047092356
A40: 1833 | B40: 4.4800994 | L40: 3.9785796 | Q40: 0.0018893396 | R40: 0.045855034
A41: 1834 | B41: 6.8694425 | L41: 6.9801895 | Q41: 0.0028366209 | R41: 0.069455049
A42: 1835 | B42: 7.7501446 | L42: 7.7490331 | Q42: 0.0025900628 | R42: 0.084788459
A43: 1836 | B43: 7.6308145 | L43: 8.3558834 | Q43: 0.0021769538 | R43: 0.10494628
A44: 1837 | B44: 6.2073302 | L44: 7.3796585 | Q44: 0.0021169987 | R44: 0.11412528
... A56: 1849 | B56: 11.531338 | L56: 12.776862 | Q56: 0.0015487585 | R56: 0.92974819
A57: 1850 | B57: 14.905336 | C57: 0.52575018 | E57: 0.50436047 | F57: 0.28564234 | G57: 0.33002373 | H57: 1.4436335 | L57: 17.983106 | M57: 0.31561833 | O57: 0.10314682 | P57: 0.20355474 | Q57: 0.0040963482 | R57: 0.85879724
A58: 1851 | B58: 15.073724 | C58: 0.92203869 | E58: 0.89309916 | F58: 2.1712886 | G58: 0.65116244 | H58: 2.1236312 | L58: 16.587491 | M58: 0.38383373 | O58: 0.16932924 | P58: 0.36153354 | Q58: 0.0050539391 | R58: 0.57490858
A59: 1852 | B59: 21.96152 | C59: 0.34426856 | E59: 0.32854509 | F59: 0.20231034 | G59: 0.19386445 | H59: 1.9708384 | L59: 62.451171 | M59: 0.36139584 | O59: 0.13721212 | P59: 0.43176816 | Q59: 0.0049963002 | R59: 0.93841573
A60: 1853 | B60: 50.735141 | C60: 0.4800285 | E60: 0.43789592 | F60: 0.4453329 | G60: 0.11178398 | H60: 2.4626268 | L60: 67.394578 | M60: 0.23090032 | O60: 0.084964833 | P60: 0.15384027 | Q60: 0.0032117543 | R60: 1.5874368
A61: 1854 | B61: 70.210718 | C61: 0.57233728 | E61: 0.46107064 | F61: 0.76257066 | G61: 0.22677795 | H61: 3.3380093 | L61: 60.757568 | M61: 0.25682923 | O61: 0.099523246 | P61: 0.20933075 | Q61: 0.004602336 | R61: 2.5214291
A62: 1855 | B62: 49.205167 | C62: 0.55669654 | E62: 0.40536103 | F62: 0.7500432 | G62: 0.23864138 | H62: 3.2845329 | L62: 71.654666 | M62: 0.18595031 | O62: 0.10679701 | P62: 0.16129824 | Q62: 0.0032578288 | R62: 2.149576
A63: 1856 | B63: 59.29479 | C63: 0.49149883 | E63: 0.35811743 | F63: 0.55798657 | G63: 0.26813931 | H63: 3.0301442 | L63: 70.313954 | M63: 0.17723022 | O63: 0.088891331 | P63: 0.1084597 | Q63: 0.0024739584 | R63: 1.5251332
A64: 1857 | B64: 70.899808 | C64: 0.49042895 | E64: 0.39900989 | F64: 0.54548866 | G64: 0.2303346 | H64: 4.1104143 | L64: 62.624413 | M64: 0.19798675 | O64: 0.10261782 | P64: 0.13248363 | Q64: 0.0025318392 | R64: 2.4626697
A65: 1858 | B65: 76.337736 | C65: 0.51541768 | E65: 0.44488857 | F65: 0.37526679 | G65: 0.22540865 | H65: 4.9025439 | L65: 70.744439 | M65: 0.28460321 | O65: 0.14545297 | P65: 0.17102085 | Q65: 0.0038701312 | R65: 3.1008477
A66: 1859 | B66: 78.446551 | C66: 0.64366415 | E66: 0.59278204 | F66: 0.90143921 | G66: 0.35238031 | H66: 6.383238 | L66: 73.821357 | M66: 0.38166578 | O66: 0.15334184 | P66: 0.32737271 | Q66: 0.0050990243 | R66: 3.6513646
A67: 1860 | B67: 72.900026 | C67: 0.48609998 | E67: 0.43499258 | F67: 0.8891814 | G67: 0.21094044 | H67: 6.3360342 | L67: 65.317096 | M67: 0.27293281 | O67: 0.12170759 | P67: 0.23146667 | Q67: 0.0046235499 | R67: 1.5391522
...

Sheet Summary
B1: Oceania
X2: Number countries
B3: Current prices | J3: Constant prices | U3: Current prices | AA3: Constant prices
B4: Current prices, current borders | F4: Current prices, 1913 borders | J4: Constant prices, current borders | N4: Constant prices, 1913 borders | S4: current borders | V4: 1913 borders | Y4: current borders | AB4: 1913 borders
B5: Imports | D5: Exports | F5: Imports | H5: Exports | J5: Imports | L5: Exports | N5: Imports | P5: Exports | S5: import | T5: export | V5: import | W5: export | Y5: import | Z5: export | AB5: import | AC5: export
B6: Millon US $ | D6: Millon US $ | F6: Millon US $ | H6: Millon US $ | J6: Millons US $1913 | L6: Millons US $1913 | N6: Millons US $1913 | P6: Millons US $1913
A7: 1800 | B7: =+SUM('Current prices, current borders'!B7:I7) -> 0 | D7: =+SUM('Current prices, current borders'!L7:S7) -> 0 | F7: =+SUM('Current prices, 1913 borders'!B7:I7) -> 0 | H7: =+SUM('Current prices, 1913 borders'!L7:S7) -> 0 | J7: =+SUM('Constant prices, current border'!B7:I7) -> 0 | L7: =+SUM('Constant prices, current border'!L7:S7) -> 0 | N7: =+SUM('Constant prices, 1913 borders'!B7:I7) -> 0 | P7: =+SUM('Constant prices, 1913 borders'!L7:S7) -> 0 | S7: =+COUNT('Current prices, current borders'!B7:I7) -> 0 | T7: =+COUNT('Current prices, current borders'!L7:S7) -> 0 | V7: =+COUNT('Current prices, 1913 borders'!B7:I7) -> 0 | W7: =+COUNT('Current prices, 1913 borders'!L7:S7) -> 0 | Y7: =+COUNT('Constant prices, current border'!B7:I7) -> 0 | Z7: =+COUNT('Constant prices, current border'!L7:S7) -> 0 | AB7: =+COUNT('Constant prices, 1913 borders'!B7:I7) -> 0 | AC7: =+COUNT('Constant prices, 1913 borders'!L7:S7) -> 0
A8: 1801 | B8: =+SUM('Current prices, current borders'!B8:I8) -> 0 | D8: =+SUM('Current prices, current borders'!L8:S8) -> 0 | F8: =+SUM('Current prices, 1913 borders'!B8:I8) -> 0 | H8: =+SUM('Current prices, 1913 borders'!L8:S8) -> 0 | J8: =+SUM('Constant prices, current border'!B8:I8) -> 0 | L8: =+SUM('Constant prices, current border'!L8:S8) -> 0 | N8: =+SUM('Constant prices, 1913 borders'!B8:I8) -> 0 | P8: =+SUM('Constant prices, 1913 borders'!L8:S8) -> 0 | S8: =+COUNT('Current prices, current borders'!B8:I8) -> 0 | T8: =+COUNT('Current prices, current borders'!L8:S8) -> 0 | V8: =+COUNT('Current prices, 1913 borders'!B8:I8) -> 0 | W8: =+COUNT('Current prices, 1913 borders'!L8:S8) -> 0 | Y8: =+COUNT('Constant prices, current border'!B8:I8) -> 0 | Z8: =+COUNT('Constant prices, current border'!L8:S8) -> 0 | AB8: =+COUNT('Constant prices, 1913 borders'!B8:I8) -> 0 | AC8: =+COUNT('Constant prices, 1913 borders'!L8:S8) -> 0
A9: 1802 | B9: =+SUM('Current prices, current borders'!B9:I9) -> 0 | D9: =+SUM('Current prices, current borders'!L9:S9) -> 0 | F9: =+SUM('Current prices, 1913 borders'!B9:I9) -> 0 | H9: =+SUM('Current prices, 1913 borders'!L9:S9) -> 0 | J9: =+SUM('Constant prices, current border'!B9:I9) -> 0 | L9: =+SUM('Constant prices, current border'!L9:S9) -> 0 | N9: =+SUM('Constant prices, 1913 borders'!B9:I9) -> 0 | P9: =+SUM('Constant prices, 1913 borders'!L9:S9) -> 0 | S9: =+COUNT('Current prices, current borders'!B9:I9) -> 0 | T9: =+COUNT('Current prices, current borders'!L9:S9) -> 0 | V9: =+COUNT('Current prices, 1913 borders'!B9:I9) -> 0 | W9: =+COUNT('Current prices, 1913 borders'!L9:S9) -> 0 | Y9: =+COUNT('Constant prices, current border'!B9:I9) -> 0 | Z9: =+COUNT('Constant prices, current border'!L9:S9) -> 0 | AB9: =+COUNT('Constant prices, 1913 borders'!B9:I9) -> 0 | AC9: =+COUNT('Constant prices, 1913 borders'!L9:S9) -> 0
A10: 1803 | B10: =+SUM('Current prices, current borders'!B10:I10) -> 0 | D10: =+SUM('Current prices, current borders'!L10:S10) -> 0 | F10: =+SUM('Current prices, 1913 borders'!B10:I10) -> 0 | H10: =+SUM('Current prices, 1913 borders'!L10:S10) -> 0 | J10: =+SUM('Constant prices, current border'!B10:I10) -> 0 | L10: =+SUM('Constant prices, current border'!L10:S10) -> 0 | N10: =+SUM('Constant prices, 1913 borders'!B10:I10) -> 0 | P10: =+SUM('Constant prices, 1913 borders'!L10:S10) -> 0 | S10: =+COUNT('Current prices, current borders'!B10:I10) -> 0 | T10: =+COUNT('Current prices, current borders'!L10:S10) -> 0 | V10: =+COUNT('Current prices, 1913 borders'!B10:I10) -> 0 | W10: =+COUNT('Current prices, 1913 borders'!L10:S10) -> 0 | Y10: =+COUNT('Constant prices, current border'!B10:I10) -> 0 | Z10: =+COUNT('Constant prices, current border'!L10:S10) -> 0 | AB10: =+COUNT('Constant prices, 1913 borders'!B10:I10) -> 0 | AC10: =+COUNT('Constant prices, 1913 borders'!L10:S10) -> 0
A11: 1804 | B11: =+SUM('Current prices, current borders'!B11:I11) -> 0 | D11: =+SUM('Current prices, current borders'!L11:S11) -> 0 | F11: =+SUM('Current prices, 1913 borders'!B11:I11) -> 0 | H11: =+SUM('Current prices, 1913 borders'!L11:S11) -> 0 | J11: =+SUM('Constant prices, current border'!B11:I11) -> 0 | L11: =+SUM('Constant prices, current border'!L11:S11) -> 0 | N11: =+SUM('Constant prices, 1913 borders'!B11:I11) -> 0 | P11: =+SUM('Constant prices, 1913 borders'!L11:S11) -> 0 | S11: =+COUNT('Current prices, current borders'!B11:I11) -> 0 | T11: =+COUNT('Current prices, current borders'!L11:S11) -> 0 | V11: =+COUNT('Current prices, 1913 borders'!B11:I11) -> 0 | W11: =+COUNT('Current prices, 1913 borders'!L11:S11) -> 0 | Y11: =+COUNT('Constant prices, current border'!B11:I11) -> 0 | Z11: =+COUNT('Constant prices, current border'!L11:S11) -> 0 | AB11: =+COUNT('Constant prices, 1913 borders'!B11:I11) -> 0 | AC11: =+COUNT('Constant prices, 1913 borders'!L11:S11) -> 0
A12: 1805 | B12: =+SUM('Current prices, current borders'!B12:I12) -> 0 | D12: =+SUM('Current prices, current borders'!L12:S12) -> 0 | F12: =+SUM('Current prices, 1913 borders'!B12:I12) -> 0 | H12: =+SUM('Current prices, 1913 borders'!L12:S12) -> 0 | J12: =+SUM('Constant prices, current border'!B12:I12) -> 0 | L12: =+SUM('Constant prices, current border'!L12:S12) -> 0 | N12: =+SUM('Constant prices, 1913 borders'!B12:I12) -> 0 | P12: =+SUM('Constant prices, 1913 borders'!L12:S12) -> 0 | S12: =+COUNT('Current prices, current borders'!B12:I12) -> 0 | T12: =+COUNT('Current prices, current borders'!L12:S12) -> 0 | V12: =+COUNT('Current prices, 1913 borders'!B12:I12) -> 0 | W12: =+COUNT('Current prices, 1913 borders'!L12:S12) -> 0 | Y12: =+COUNT('Constant prices, current border'!B12:I12) -> 0 | Z12: =+COUNT('Constant prices, current border'!L12:S12) -> 0 | AB12: =+COUNT('Constant prices, 1913 borders'!B12:I12) -> 0 | AC12: =+COUNT('Constant prices, 1913 borders'!L12:S12) -> 0
A13: 1806 | B13: =+SUM('Current prices, current borders'!B13:I13) -> 0 | D13: =+SUM('Current prices, current borders'!L13:S13) -> 0 | F13: =+SUM('Current prices, 1913 borders'!B13:I13) -> 0 | H13: =+SUM('Current prices, 1913 borders'!L13:S13) -> 0 | J13: =+SUM('Constant prices, current border'!B13:I13) -> 0 | L13: =+SUM('Constant prices, current border'!L13:S13) -> 0 | N13: =+SUM('Constant prices, 1913 borders'!B13:I13) -> 0 | P13: =+SUM('Constant prices, 1913 borders'!L13:S13) -> 0 | S13: =+COUNT('Current prices, current borders'!B13:I13) -> 0 | T13: =+COUNT('Current prices, current borders'!L13:S13) -> 0 | V13: =+COUNT('Current prices, 1913 borders'!B13:I13) -> 0 | W13: =+COUNT('Current prices, 1913 borders'!L13:S13) -> 0 | Y13: =+COUNT('Constant prices, current border'!B13:I13) -> 0 | Z13: =+COUNT('Constant prices, current border'!L13:S13) -> 0 | AB13: =+COUNT('Constant prices, 1913 borders'!B13:I13) -> 0 | AC13: =+COUNT('Constant prices, 1913 borders'!L13:S13) -> 0
A14: 1807 | B14: =+SUM('Current prices, current borders'!B14:I14) -> 0 | D14: =+SUM('Current prices, current borders'!L14:S14) -> 0 | F14: =+SUM('Current prices, 1913 borders'!B14:I14) -> 0 | H14: =+SUM('Current prices, 1913 borders'!L14:S14) -> 0 | J14: =+SUM('Constant prices, current border'!B14:I14) -> 0 | L14: =+SUM('Constant prices, current border'!L14:S14) -> 0 | N14: =+SUM('Constant prices, 1913 borders'!B14:I14) -> 0 | P14: =+SUM('Constant prices, 1913 borders'!L14:S14) -> 0 | S14: =+COUNT('Current prices, current borders'!B14:I14) -> 0 | T14: =+COUNT('Current prices, current borders'!L14:S14) -> 0 | V14: =+COUNT('Current prices, 1913 borders'!B14:I14) -> 0 | W14: =+COUNT('Current prices, 1913 borders'!L14:S14) -> 0 | Y14: =+COUNT('Constant prices, current border'!B14:I14) -> 0 | Z14: =+COUNT('Constant prices, current border'!L14:S14) -> 0 | AB14: =+COUNT('Constant prices, 1913 borders'!B14:I14) -> 0 | AC14: =+COUNT('Constant prices, 1913 borders'!L14:S14) -> 0
A15: 1808 | B15: =+SUM('Current prices, current borders'!B15:I15) -> 0 | D15: =+SUM('Current prices, current borders'!L15:S15) -> 0 | F15: =+SUM('Current prices, 1913 borders'!B15:I15) -> 0 | H15: =+SUM('Current prices, 1913 borders'!L15:S15) -> 0 | J15: =+SUM('Constant prices, current border'!B15:I15) -> 0 | L15: =+SUM('Constant prices, current border'!L15:S15) -> 0 | N15: =+SUM('Constant prices, 1913 borders'!B15:I15) -> 0 | P15: =+SUM('Constant prices, 1913 borders'!L15:S15) -> 0 | S15: =+COUNT('Current prices, current borders'!B15:I15) -> 0 | T15: =+COUNT('Current prices, current borders'!L15:S15) -> 0 | V15: =+COUNT('Current prices, 1913 borders'!B15:I15) -> 0 | W15: =+COUNT('Current prices, 1913 borders'!L15:S15) -> 0 | Y15: =+COUNT('Constant prices, current border'!B15:I15) -> 0 | Z15: =+COUNT('Constant prices, current border'!L15:S15) -> 0 | AB15: =+COUNT('Constant prices, 1913 borders'!B15:I15) -> 0 | AC15: =+COUNT('Constant prices, 1913 borders'!L15:S15) -> 0
A16: 1809 | B16: =+SUM('Current prices, current borders'!B16:I16) -> 0 | D16: =+SUM('Current prices, current borders'!L16:S16) -> 0 | F16: =+SUM('Current prices, 1913 borders'!B16:I16) -> 0 | H16: =+SUM('Current prices, 1913 borders'!L16:S16) -> 0 | J16: =+SUM('Constant prices, current border'!B16:I16) -> 0 | L16: =+SUM('Constant prices, current border'!L16:S16) -> 0 | N16: =+SUM('Constant prices, 1913 borders'!B16:I16) -> 0 | P16: =+SUM('Constant prices, 1913 borders'!L16:S16) -> 0 | S16: =+COUNT('Current prices, current borders'!B16:I16) -> 0 | T16: =+COUNT('Current prices, current borders'!L16:S16) -> 0 | V16: =+COUNT('Current prices, 1913 borders'!B16:I16) -> 0 | W16: =+COUNT('Current prices, 1913 borders'!L16:S16) -> 0 | Y16: =+COUNT('Constant prices, current border'!B16:I16) -> 0 | Z16: =+COUNT('Constant prices, current border'!L16:S16) -> 0 | AB16: =+COUNT('Constant prices, 1913 borders'!B16:I16) -> 0 | AC16: =+COUNT('Constant prices, 1913 borders'!L16:S16) -> 0
A17: 1810 | B17: =+SUM('Current prices, current borders'!B17:I17) -> 0 | D17: =+SUM('Current prices, current borders'!L17:S17) -> 0 | F17: =+SUM('Current prices, 1913 borders'!B17:I17) -> 0 | H17: =+SUM('Current prices, 1913 borders'!L17:S17) -> 0 | J17: =+SUM('Constant prices, current border'!B17:I17) -> 0 | L17: =+SUM('Constant prices, current border'!L17:S17) -> 0 | N17: =+SUM('Constant prices, 1913 borders'!B17:I17) -> 0 | P17: =+SUM('Constant prices, 1913 borders'!L17:S17) -> 0 | S17: =+COUNT('Current prices, current borders'!B17:I17) -> 0 | T17: =+COUNT('Current prices, current borders'!L17:S17) -> 0 | V17: =+COUNT('Current prices, 1913 borders'!B17:I17) -> 0 | W17: =+COUNT('Current prices, 1913 borders'!L17:S17) -> 0 | Y17: =+COUNT('Constant prices, current border'!B17:I17) -> 0 | Z17: =+COUNT('Constant prices, current border'!L17:S17) -> 0 | AB17: =+COUNT('Constant prices, 1913 borders'!B17:I17) -> 0 | AC17: =+COUNT('Constant prices, 1913 borders'!L17:S17) -> 0
A18: 1811 | B18: =+SUM('Current prices, current borders'!B18:I18) -> 0 | D18: =+SUM('Current prices, current borders'!L18:S18) -> 0 | F18: =+SUM('Current prices, 1913 borders'!B18:I18) -> 0 | H18: =+SUM('Current prices, 1913 borders'!L18:S18) -> 0 | J18: =+SUM('Constant prices, current border'!B18:I18) -> 0 | L18: =+SUM('Constant prices, current border'!L18:S18) -> 0 | N18: =+SUM('Constant prices, 1913 borders'!B18:I18) -> 0 | P18: =+SUM('Constant prices, 1913 borders'!L18:S18) -> 0 | S18: =+COUNT('Current prices, current borders'!B18:I18) -> 0 | T18: =+COUNT('Current prices, current borders'!L18:S18) -> 0 | V18: =+COUNT('Current prices, 1913 borders'!B18:I18) -> 0 | W18: =+COUNT('Current prices, 1913 borders'!L18:S18) -> 0 | Y18: =+COUNT('Constant prices, current border'!B18:I18) -> 0 | Z18: =+COUNT('Constant prices, current border'!L18:S18) -> 0 | AB18: =+COUNT('Constant prices, 1913 borders'!B18:I18) -> 0 | AC18: =+COUNT('Constant prices, 1913 borders'!L18:S18) -> 0
... A145: 1938 | B145: =+SUM('Current prices, current borders'!B145:I145) -> 789.0069 | D145: =+SUM('Current prices, current borders'!L145:S145) -> 797.73646 | F145: =+SUM('Current prices, 1913 borders'!B145:I145) -> 789.0069 | H145: =+SUM('Current prices, 1913 borders'!L145:S145) -> 797.73646 | J145: =+SUM('Constant prices, current border'!B145:I145) -> 785.62917 | L145: =+SUM('Constant prices, current border'!L145:S145) -> 830.86178 | N145: =+SUM('Constant prices, 1913 borders'!B145:I145) -> 785.62917 | P145: =+SUM('Constant prices, 1913 borders'!L145:S145) -> 830.86178 | S145: =+COUNT('Current prices, current borders'!B145:I145) -> 5 | T145: =+COUNT('Current prices, current borders'!L145:S145) -> 5 | V145: =+COUNT('Current prices, 1913 borders'!B145:I145) -> 5 | W145: =+COUNT('Current prices, 1913 borders'!L145:S145) -> 5 | Y145: =+COUNT('Constant prices, current border'!B145:I145) -> 5 | Z145: =+COUNT('Constant prices, current border'!L145:S145) -> 5 | AB145: =+COUNT('Constant prices, 1913 borders'!B145:I145) -> 5 | AC145: =+COUNT('Constant prices, 1913 borders'!L145:S145) -> 5
